Workbook

Sheet Start
A1: Physics PhD Atlas 2027: planner workbook
A2: Version 1.1 · 82 programs · data checked October 22, 2026
A4: 1. Programs: every program with deadline, fee, waivers, tests, supervisor rule and funding. Filter with the header arrows.
A5: 2. Shortlist: choose a program from the drop-down in column A; the other columns fill in automatically. Yellow cells are yours to edit.
A6: 3. Budget: totals your shortlisted application fees by currency. Add score-sending and transcript costs from the official sites, and today's exchange rates.
A7: 4. Recommenders and Supervisor outreach: track requests; follow-up dates calculate themselves.
A8: 5. Sources: the exact official sentence and link behind every value.
A10: 'Not stated' = the official pages checked did not say (not a 'no'). Always confirm on the official page before paying or submitting.
A11: Not affiliated with any university. Not immigration, visa or legal advice.

Sheet Programs
A1: Program | B1: Institution and department | C1: Country | D1: Region | E1: Deadline | F1: Deadline note | G1: Fee amount | H1: Fee currency | I1: Intl fee waiver | J1: Fee waiver detail | K1: GRE General | L1: Physics GRE | M1: TOEFL minimum | N1: English waiver | O1: English detail | P1: Supervisor | Q1: Supervisor detail | R1: Funding | S1: Funding detail | T1: Entry route | U1: Notes | V1: Admissions page | W1: Checked
A2: Aalto | B2: Aalto University · Doctoral Programme in Science (SCI), School of Science (incl. Applied Physics) | C2: Finland | D2: Uusimaa (Espoo) | E2: Rolling | F2: Continuous admission with roughly monthly cut-offs (nothing is processed in July); the last 2026 cut-offs are 3 Nov and 1 Dec 2026. Salaried doctoral researcher positions are advertised and applied for separately | G2: Not stated | I2: Not stated | J2: Not stated on the page checked | K2: Not stated | L2: Not stated | M2: 92 | N2: Yes | O2: India is on Aalto's list: an English-medium degree (at least a 3-year bachelor's or a 1-year master's), at least half completed in English while living in India, counts if the language is stated on the certificate or transcript | P2: Required | Q2: You must have a supervising professor in your intended research field before you submit the application | R2: Competitive | S2: Not automatic: fund the PhD through a salaried doctoral researcher position (advertised separately) or grants. A full-time study right needs funding secured for at least 6 months; unfunded part-time study is possible in some cases. No tuition fees | T2: Master's usually required | U2: Physics is one of the fields of the Aalto Doctoral Programme in Science (School of Science, e.g. Department of Applied Physics). There are two routes: get a salaried doctoral researcher position first and then apply for the study right, or apply for the study right with other funding. The language rules are labelled for 2026 admissions, and the TOEFL minimum is given only on the old 0-120 scale. Cut-off dates for 2027 were not yet published. | V2: https://www.aalto.fi/en/study-options/aalto-doctoral-programme-in-science-0 | W2: 2026-10-21
A3: Boston University | B3: Boston University · Department of Physics | C3: USA | D3: Massachusetts | E3: 46371 | F3: December 15, 23:59 ET; all documents must be posted. Year inferred. | G3: 95 | H3: USD | I3: Domestic only | J3: Central office waivers are domestic-only; international applicants may ask the program directly | K3: Optional | L3: Recommended | M3: Not stated | N3: Not stated | O3: Not stated on the page checked | P3: Not stated | Q3: No pre-application supervisor requirement mentioned | R3: Typical | S3: RAs and TAs receive tuition, fees and basic medical insurance plus a stipend | T3: Not stated | U3: BU explicitly refuses hardship-based fee waivers for international applicants at the central level. | V3: https://www.bu.edu/physics/graduate-program/graduate-program-admissions/ | W3: 2026-10-21
A4: Caltech | B4: California Institute of Technology · Department of Physics (PMA) | C4: USA | D4: California | E4: 46371 | F4: December 15 (catalog). Year inferred for Fall 2027. | G4: Not stated | I4: Limited | J4: Waivers are requested inside the online application; eligibility rules are not stated on the department page | K4: Recommended | L4: Required | M4: Not stated | N4: Not stated | O4: Not stated on the page checked | P4: Not stated | Q4: No pre-application supervisor requirement mentioned | R4: Not stated | S4: Not stated on the page checked | T4: Not stated | U4: Astronomy faculty can supervise physics students and vice versa. | V4: https://physics.caltech.edu/academics/graduate-studies/information-for-applicants | W4: 2026-10-21
A5: Carleton University | B5: Carleton University · Department of Physics | C5: Canada | D5: Ontario | E5: 46402 | F5: January 15 (Fall entry); late applications considered if openings remain. Year inferred for Fall 2027. | G5: 125 | H5: CAD | I5: None | J5: Graduate application fees are not waived | K5: Not stated | L5: Not stated | M5: 86 | N5: No | O5: Exemption only for English-taught degrees from countries whose primary language is English (India does not qualify) or a recent Canadian degree; medium-of-instruction letters are explicitly not accepted | P5: Not stated | Q5: Not stated on the page checked | R5: Competitive | S5: University-level statement: applicants are automatically considered for admission funding (TA, research stipend, scholarships) and notified in the offer if eligible; no guaranteed minimum stated on the pages checked | T5: Master's usually required | U5: PhD streams: Particle Physics and Medical Physics (CAMPEP-accredited), run jointly with uOttawa through the Ottawa-Carleton Institute for Physics. The department site (physics.carleton.ca) returned errors on every fetch, so supervisor and GRE policy could not be checked. | V5: https://graduate.carleton.ca/program/physics-doctoral-programs/ | W5: 2026-10-21
A6: Chalmers | B6: Chalmers University of Technology · Graduate School in Physics, Department of Physics and Astronomy | C6: Sweden | D6: Västra Götaland (Gothenburg) | E6: Per position | F6: No central deadline: doctoral positions are advertised under Vacant positions throughout the year, each with its own deadline | G6: 0 | I6: No fee | J6: No fee to waive | K6: Not stated | L6: Not stated | M6: 90 | N6: Conditional | O6: Indian upper-secondary English can meet the requirement: CBSE (2008 onwards) or CISCE Class XII English grades, or an English-medium upper secondary certificate. The India page offers no degree-based route, so otherwise take a test | P6: Not stated | Q6: Not stated on the page checked | R6: Guaranteed | S6: Doctoral students are employed by Chalmers on a monthly salary (fixed-term, generally at most five years), with up to 20% teaching or departmental work | T6: Master's usually required | U6: The Graduate School in Physics is run by the Department of Physics and Astronomy. Its syllabus sections (including entry requirements) are collapsed on the page and did not appear in the text checked, so the rules above are Chalmers-wide. Licentiate after about two years; doctorate after four to five years. | V6: https://www.chalmers.se/en/research/doctoral-studies/graduate-schools/physics/ | W6: 2026-10-21
A7: Columbia | B7: Columbia University · Department of Physics | C7: USA | D7: New York | E7: 46359 | F7: December 3, 2026 for Fall 2027 (early!) | G7: 120 | H7: USD | I7: Available | J7: GSAS considers waivers for financial need, personal hardship or other onerous circumstances | K7: Optional | L7: Optional | M7: Not stated | N7: Conditional | O7: Rule is based on the official language of your degree institution's country; English is an official language in India, so ask GSAS how this applies to you | P7: Not stated | Q7: No pre-application supervisor requirement mentioned | R7: Guaranteed | S7: Prevailing stipend plus tuition and fees for six years in good standing | T7: Not stated | U7: Three letters; personal statement. One of the earliest deadlines in this list. | V7: https://www.physics.columbia.edu/content/applying-columbia-physics-graduate-program | W7: 2026-10-21
A8: Cornell | B8: Cornell University · Department of Physics | C8: USA | D8: New York | E8: 46371 | F8: December 15: all materials incl. test scores must be received. Year inferred. | G8: 105 | H8: USD | I8: Available | J8: Can be requested for financial hardship or extenuating circumstances (Graduate School criteria) | K8: Not stated | L8: Required | M8: Sections | N8: Not stated | O8: Standing exemptions on the Graduate School site (not checked) | P8: Not stated | Q8: No pre-application supervisor requirement mentioned | R8: Guaranteed | S8: 6 years of full support in good standing (fellowships, TA, RA) | T8: Direct from bachelor's | U8: Applied Physics (AEP) is a separate Cornell field with different GRE rules. | V8: https://physics.cornell.edu/prospective-graduate-students | W8: 2026-10-21
A9: Dalhousie University | B9: Dalhousie University · Department of Physics and Atmospheric Science | C9: Canada | D9: Nova Scotia | E9: 46478 | F9: Formal application: April 1 for non-Canadian applicants for September admission (FGS general deadline; Canadians June 1). Free department pre-application first, reviewed September 1 to April 30, so start well before. Year inferred for September 2027. | G9: 115 | H9: CAD | I9: Not stated | J9: Not stated on the page checked | K9: Not required | L9: Not required | M9: 92 | N9: Conditional | O9: Waiver can be requested (not automatic) if your degree is from a recognized university with English as the language of instruction in a country where English is an official language; English is an official language of India, but confirm the waiver with the program | P9: Required | Q9: Admission depends on finding a supervisor through the free pre-application/interview; the formal application is submitted only with a supervisor's support and names the supervisor | R9: Guaranteed | S9: Every full-time MSc/PhD student funded; for students of primary-appointment faculty, guaranteed at least CAD 2,000/month take-home on average (CAD 24,000/yr after tuition) and CAD 33,000/yr total; PhD support normally 4 years; internationals funded on the same terms | T9: Either | U9: Apply via a free department pre-application first; a professor interviews you and funding is fixed before the formal FGS application. International PhD tuition equals domestic. Department Graduate Scholarship (CAD 20,000/yr, GPA 3.7+) open to internationals. | V9: https://www.dal.ca/faculty/science/physics/graduate/apply.html | W9: 2026-10-21
A10: TU Delft | B10: Delft University of Technology · Faculty of Applied Sciences (TNW), applied physics departments | C10: Netherlands | D10: South Holland (Delft) | E10: Per position | F10: No central deadline: apply to a specific advertised PhD position (each vacancy has its own deadline) | G10: Not stated | I10: Not stated | J10: Not stated on the pages checked | K10: Not stated | L10: Not stated | M10: 100 | N10: Yes | O10: In principle exempt with an English-taught master's degree; if your English is judged insufficient during selection you may be asked to take a placement test at TU Delft | P10: Required | Q10: You apply to a specific position and are employed in your supervisor's department; the application process includes a conversation with the professor | R10: Typical | S10: Regular PhD positions are four-year employment contracts with a salary under the Dutch universities' collective labour agreement; if no position is available you must find your own scholarship or grant | T10: Master's usually required | U10: The Faculty of Applied Sciences (TNW) houses the applied-physics departments (e.g. Quantum Nanoscience, Imaging Physics, Radiation Science & Technology, Bionanoscience). TU Delft lists a PhD tuition fee of EUR 11,000 per PhD programme plus an annual bench fee. The bench fee is charged to the institute you work for, or to you if no institute funds you. Who pays is agreed at the start, and the faculty may waive either fee. Teaching is capped at 20% of the appointment. | V10: https://www.tudelft.nl/en/faculty-of-applied-sciences/research/phd | W10: 2026-10-21
A11: Durham | B11: Durham University · Department of Physics | C11: United Kingdom | D11: England | E11: 46371 | F11: Departmental deadline Dec 15, 2026: applications by then get full consideration for all scholarships and funding. Later applications are still considered, but may be eligible only for some scholarships. There is no set deadline for admission itself. | G11: Not stated | I11: Not stated | J11: Not stated on the page checked | K11: Not stated | L11: Not stated | M11: 4.5 (new scale) | N11: No | O11: Exemption needs at least 1 full academic year of a degree studied in the UK or another majority English-speaking country (within 2 years of the start), or a UK-degree-equivalent qualification from (or nationality of) a listed country. India is not on the list. Physics may interview you without a test certificate, but still requires one. | P11: Recommended | Q11: University guidance says to contact a potential supervisor before applying. Physics lets you apply to a research area and list the staff you would like to consider your application, and does not state that prior agreement is required. | R11: Competitive | S11: Funded studentships (UK Research Councils, external sponsors, Durham) are typically available in all research areas; apply by Dec 15, 2026 for full consideration for all scholarships and funding | T11: Either | U11: The department advises not submitting before mid-October because a new admissions system has just gone live. One application covers several projects or research areas. | V11: https://www.durham.ac.uk/departments/academic/physics/postgraduate-study/research-degrees/how-to-apply/ | W11: 2026-10-21
A12: EPFL | B12: EPFL (École polytechnique fédérale de Lausanne) · Doctoral Program in Physics (EDPY) | C12: Switzerland | D12: Vaud (Lausanne) | E12: 46507 | F12: Two rounds a year: October 31 and April 30. Next: Oct 31, 2026 (imminent) and Apr 30, 2027. Complete files incl. 3 letters. Years inferred. | G12: 0 | I12: No fee | J12: Not needed: no application fee | K12: Recommended | L12: Not stated | M12: Not stated | N12: Yes | O12: No English test is strictly required; proficiency in English is required and TOEFL is strongly recommended | P12: Required | Q12: Admission = eligible by committee AND a thesis advisor offers you a PhD position after interview; eligible files are shared with all thesis directors | R12: Guaranteed | S12: Enrolment requires secured funding; lab-appointed doctoral students get an employment contract | T12: Master's usually required | U12: French not required to start; visas/work permits take about 3 months after appointment. | V12: https://www.epfl.ch/education/phd/edpy-physics/edpy-how-to-apply/ | W12: 2026-10-21
A13: ETH Zurich | B13: ETH Zurich · Department of Physics (D-PHYS) | C13: Switzerland | D13: Zurich | E13: Per position | F13: No central deadline: each professor recruits their own doctoral students; some posts are advertised as vacancies | G13: Not stated | I13: Not stated | J13: Not stated on the page checked | K13: Not stated | L13: Not stated | M13: Not stated | N13: Not stated | O13: Not stated on the page checked; ask the professor | P13: Required | Q13: A professor must agree to supervise you; contact professorships directly (the Doctoral Administration does not match candidates) | R13: Typical | S13: With few exceptions doctorates are linked to a position (employment) at ETH or in the ETH Domain | T13: Not stated | U13: Individual doctorate model: no overarching doctoral school. See the AVETH survival guide linked from the page. | V13: https://ethz.ch/en/doctorate/finding-a-place.html | W13: 2026-10-21
A14: Georgia Tech | B14: Georgia Institute of Technology · School of Physics | C14: USA | D14: Georgia | E14: 46371 | F14: December 15. Year inferred for Fall 2027. | G14: 105 | H14: USD | I14: Limited | J14: Institute waivers for outstanding undergraduate achievement or recruitment events; internationals must submit ALL materials (incl. English scores) before requesting | K14: Not required | L14: Not required | M14: 106 | N14: No | O14: All applicants must demonstrate English proficiency at application, regardless of citizenship | P14: Not stated | Q14: No pre-application supervisor requirement mentioned | R14: Not stated | S14: PhD support terms not stated (MS students get no support) | T14: Direct from bachelor's | U14: Very high English-test thresholds: plan test dates early. | V14: https://physics.gatech.edu/academics/graduate/admissions-info | W14: 2026-10-21
A15: Harvard University | B15: Harvard University · Department of Physics (Harvard Kenneth C. Griffin GSAS) | C15: USA | D15: Massachusetts | E15: 46371 | F15: December 15, 2026 at 05:00 pm (PhD) | G15: 105 | H15: USD | I15: Not stated | J15: A waiver exists; eligibility is decided by questions inside the application fee section. Whether international applicants qualify is not stated. | K15: Optional | L15: Required | M15: 95 | N15: Yes | O15: Exempt if your undergraduate degree is from an institution where English is the primary language of instruction; a master's or other graduate degree does not count | P15: Not stated | Q15: No pre-application supervisor requirement mentioned | R15: Guaranteed | S15: Guaranteed funding for the first five years for all PhD students | T15: Direct from bachelor's | U15: Department site (physics.harvard.edu) blocked automated fetches (403), so facts come from Harvard Griffin GSAS pages. GSAS accepts up to three applications per year to different programs, each with its own fee. | V15: https://gsas.harvard.edu/program/physics | W15: 2026-10-21
A16: Heidelberg (HGSFP) | B16: Heidelberg University · Heidelberg Graduate School for Physics (HGSFP) | C16: Germany | D16: Baden-Württemberg | E16: 46327 | F16: Application portal deadline November 1 (for international students and anyone without prior funding). Year inferred: Nov 1, 2026. | G16: Not stated | I16: Not stated | J16: Not stated on the pages checked | K16: Not stated | L16: Not stated | M16: Not stated | N16: Not stated | O16: Not stated on the pages checked | P16: Not required | Q16: Two routes: the web portal (international students, or anyone without funding) or direct application with an advisor and funding already arranged | R16: Not stated | S16: The portal route is for applicants without prior financial support; funding terms are not stated on the pages checked | T16: Master's usually required | U16: Degree awarded: Dr. rer. nat. | V16: https://hgsfp.physik.uni-heidelberg.de/howtoapply#start | W16: 2026-10-21
A17: IMPRS Astronomy (Heidelberg) | B17: Heidelberg University and Max Planck Institute for Astronomy (MPIA) · IMPRS for Astronomy and Cosmic Physics (IMPRS-HD) | C17: Germany | D17: Baden-Württemberg | E17: 46329 | F17: Nov 3, 2026, 14:00 CET for fall 2027 entry; the application and both reference letters must arrive by then. Interviews Feb 1–5, 2027 | G17: Not stated | I17: Not stated | J17: Not stated on the page checked | K17: Not stated | L17: Not stated | M17: Not stated | N17: Yes | O17: No English test required; communication skills are checked at interview (optional proof may help non-native speakers) | P17: Not required | Q17: A central committee screens applications; shortlisted files go to all potential supervisors and an interested supervisor triggers an interview. The project supervisor makes the final offer | R17: Guaranteed | S17: Official offers come with funding, typically a 3+1-year contract; MSc holders get about EUR 1,800–2,000 net/month (amount and terms depend on the funding source) | T17: Master's usually required | U17: Dr. rer. nat. in astrophysics; six Heidelberg institutes (MPIA, MPIK, ARI, LSW, ITA, HITS). Admitted students register with the Department of Physics and Astronomy via HGSFP. Use reference number IMPRS2027 in the application system. Germany requires a grade of 2.0 or better (about B+). | V17: https://www.imprs-hd.mpg.de/3192/Application | W17: 2026-10-21
A18: ICFO (Barcelona) | B18: ICFO – The Institute of Photonic Sciences · PhD in Photonics (with UPC Doctoral School) | C18: Spain | D18: Catalonia (Castelldefels, Barcelona) | E18: Per position | F18: Apply only through calls/openings on ICFOjobs, each with its own deadline. No PhD call was open on 2026-10-21; candidates may contact group leaders meanwhile. | G18: Not stated | I18: Not stated | J18: Not stated on the page checked | K18: Not stated | L18: Not stated | M18: Not stated | N18: Not stated | O18: No English test or waiver rule stated on the page checked | P18: Required | Q18: Admission needs a pass from the admissions committee after interview AND an offer from at least one host research group with confirmed fellowship funding | R18: Guaranteed | S18: All admitted students are fully funded through (competitive) fellowships for the whole PhD; fellowships cover a 6-month trainee period plus a 4-year PhD period | T18: Master's usually required | U18: Photonics PhD awarded with UPC. Selection: eligibility and admissibility checks, committee evaluation, on-site interviews; under 10% of applicants admitted. Applicants who already hold a PhD are not eligible. Self-funded or external fellowships (e.g. LaCaixa INPhINIT) are also possible. | V18: https://www.icfo.eu/studies/phd-program/ | W18: 2026-10-21
A19: Imperial College London | B19: Imperial College London · Department of Physics | C19: United Kingdom | D19: England | E19: 46328 | F19: President's PhD Scholarship (college-wide, open to all nationalities) rounds: apply by Nov 2, 2026, Jan 11, 2027 or Mar 1, 2027 (23:59 UK time). Physics accepts PhD applications all year; the Theory group lists a Feb 1 deadline 'each year' (shown with the 2026 date). | G19: 0 | I19: No fee | J19: PhD applications carry no application fee, so no waiver is needed | K19: Not stated | L19: Not stated | M19: Not stated | N19: No | O19: Exempt only with a UK-degree-equivalent qualification from a listed country (Australia, Canada, Guyana, Ireland, Malta, New Zealand, South Africa, UK, USA, West Indies); India is not listed | P19: Not required | Q19: Not needed before applying: the Theory group says you need not contact a supervisor, and the Matter community considers you for all available projects. Naming a preferred supervisor helps route your application (Light community). Exception: President's PhD Scholarship applicants must already have a supervisor who has agreed to supervise them. | R19: Competitive | S19: A limited number of fully funded studentships (fees and living costs). Studentships for overseas applicants are very restricted: most overseas students bring home-country scholarships or self-fund (Matter community page). President's PhD Scholarships are open to all nationalities but very competitive. | T19: Direct from bachelor's | U19: There is no single Physics PhD course page; details come from the research-community pages (Light, Matter, Theory), and several still show 2026-cycle dates. Imperial's English levels are TOEFL 92 (Standard) or 100 (Higher), or 4.5/5.0 on the new scale. | V19: https://www.imperial.ac.uk/natural-sciences/departments/physics/students/postgraduate-admissions/phd-opportunities/ | W19: 2026-10-21
A20: Indiana University Bloomington | B20: Indiana University Bloomington · Department of Physics | C20: USA | D20: Indiana | E20: 46371 | F20: December 15 (year inferred); international documents must be received by then. Later applications considered only if positions remain. Dept also calls Dec 15 the priority date. | G20: 70 | H20: USD | I20: None | J20: Department states no fee waivers are granted | K20: Optional | L20: Recommended | M20: 80 | N20: No | O20: No exemption route shown for graduate applicants: non-native speakers may be required to test regardless of where educated, and all non-native speakers seeking any financial aid must submit TOEFL/IELTS/Duolingo | P20: Not stated | Q20: Not stated on the page checked | R20: Typical | S20: PhD package typically provides full funding (TA/RA stipend plus tuition waiver covering most tuition) | T20: Not stated | U20: Domestic-applications page lists graduation from a recognized four-year college and GPA 3.0 on transcripts. Separate Astrophysics, Chemical Physics and Mathematical Physics PhDs exist. | V20: https://physics.indiana.edu/graduate/how-to-apply/international-applications.html | W20: 2026-10-21
A21: Johns Hopkins University | B21: Johns Hopkins University · William H. Miller III Department of Physics & Astronomy | C21: USA | D21: Maryland | E21: 46371 | F21: December 15 preceding September entry; year inferred. Vivien Thomas Scholars Initiative applicants must submit by Dec 1. | G21: 75 | H21: USD | I21: Not stated | J21: Page says the fee may be waived but gives no criteria; international eligibility not stated (JHU graduate admissions site blocked automated fetches) | K21: Optional | L21: Optional | M21: 100 | N21: Not stated | O21: Page requires TOEFL or IELTS for international students; exemption rules not shown on the page checked | P21: Not stated | Q21: No pre-application supervisor requirement mentioned | R21: Guaranteed | S21: All graduate students are appointed as TAs or RAs, which provide tuition, stipend and benefits | T21: Direct from bachelor's | U21: JHU graduate admissions and Krieger school sites blocked automated fetches (403). Admitted PhD students can apply for a $1,500 need-based relocation grant. | V21: https://physics-astronomy.jhu.edu/graduate/admissions/ | W21: 2026-10-21
A22: KTH Stockholm | B22: KTH Royal Institute of Technology · Doctoral Programme in Physics, School of Engineering Sciences (SCI) | C22: Sweden | D22: Stockholm | E22: Per position | F22: No central deadline: apply to an advertised doctoral position; KTH announces positions nine times a year (Feb-Jun, Sep-Dec), each with its own deadline | G22: Not stated | I22: Not stated | J22: Not stated on the page checked | K22: Not stated | L22: Not stated | M22: 90 | N22: Conditional | O22: Indian upper-secondary English can meet the requirement: CBSE (2008 onwards) or CISCE Class XII English grades, or an English-medium upper secondary certificate. The India page offers no degree-based route, so otherwise take a test | P22: Required | Q22: You apply to a specific advertised position; the final admission decision is made by the head of school in consultation with the intended supervisors | R22: Guaranteed | S22: People admitted to advertised positions are employed by KTH on a monthly salary, currently starting at SEK 33,000 and rising to SEK 37,100 per month | T22: Master's usually required | U22: KTH's Doctoral Program in Physics (School of Engineering Sciences) has six specialisations; the application rules are KTH-wide. A PhD is four years full-time, with up to 20% departmental duties. English rules point to University Admissions in Sweden (universityadmissions.se), which KTH links to; its India rules are written for master's admission and KTH says the doctoral requirement is the same. | V22: https://www.kth.se/en/sci/utbildning/forskarutbildning/forskaramnet-fysik-1.795636 | W22: 2026-10-21
A23: Munich (MCQST) | B23: LMU / TUM / Max Planck (Munich) · MCQST Doctoral Fellowships in Quantum Science & Technology (formerly IMPRS-QST) | C23: Germany | D23: Bavaria (Munich) | E23: Not stated | F23: Call opens October 2026 for Fall 2027; deadline not yet published on the page checked | G23: Not stated | I23: Not stated | J23: Not stated on the page checked | K23: Not stated | L23: Not stated | M23: Not stated | N23: Not stated | O23: Not stated | P23: Not stated | Q23: Not stated on the page checked | R23: Not stated | S23: Doctoral fellowships; terms not stated on the page checked | T23: Not stated | U23: One shared platform: apply for the MCQST fellowship, the Munich Quantum Valley (MQV) fellowship, or both. IMPRS-QST no longer runs a separate program. | V23: https://www.imprs-quantum.mpg.de/3192/Application | W23: 2026-10-21
A24: Leiden | B24: Leiden University · Leiden Institute of Physics (LION) | C24: Netherlands | D24: South Holland (Leiden) | E24: Per position | F24: Paid PhD positions are advertised as vacancies with their own deadlines | G24: Not stated | I24: Not stated | J24: Not stated on the pages checked | K24: Not stated | L24: Not stated | M24: Not stated | N24: Not stated | O24: Not stated on the pages checked (theses are written in English) | P24: Required | Q24: Apply to a specific advertised position; requirements are set with the thesis supervisor | R24: Guaranteed | S24: All LION PhD projects are 4-year fully paid positions (usually a 1+3-year contract) with about 10% teaching | T24: Master's usually required | U24: Self-funded entry possible with grants covering living costs and a bench fee. | V24: https://www.universiteitleiden.nl/en/science/physics/phd-programme | W24: 2026-10-21
A25: Massachusetts Institute of Technology | B25: Massachusetts Institute of Technology · Department of Physics | C25: USA | D25: Massachusetts | E25: 46371 | F25: December 15 at 11:59 PM Eastern (application opens September 15); year inferred | G25: 90 | H25: USD | I25: Limited | J25: International applicants qualify only if currently at a US college AND in a select research-preparation program; no hardship-only waivers for internationals. Requests due Dec 1 for Dec 15 deadlines. | K25: Recommended | L25: Recommended | M25: 100 | N25: No | O25: Automatic exemption only for undergraduate degrees from Australia, Canada, Ireland, New Zealand, UK or US; English-medium degrees from other countries (e.g. India) explicitly do not qualify. Physics says a department waiver "may be available" (discretionary, requested in the application). | P25: Not stated | Q25: No pre-application supervisor requirement mentioned | R25: Guaranteed | S25: PhD students fully supported for the whole program, given satisfactory progress (tuition, health insurance, stipend) | T25: Not stated | U25: physics.mit.edu blocked automated fetches (403, also with a headless browser), so facts come from the MIT Office of Graduate Education program page. OGE grants up to three fee waivers per applicant. | V25: https://oge.mit.edu/programs/physics/ | W25: 2026-10-21
A26: IMPRS Quantum Materials (Dresden) | B26: Max Planck Institute for Chemical Physics of Solids (MPI CPfS) and TU Dresden · IMPRS for Chemistry and Physics of Quantum Materials (IMPRS-CPQM) | C26: Germany | D26: Saxony | E26: 46356 | F26: Nov 30, 2026 for the 2026/27 recruitment cycle (selection workshop in Dresden Feb 22–24, 2027; start by Sept 2027). Applications outside the cycle are accepted year-round and handled individually | G26: 0 | I26: No fee | J26: Not needed: no application fee | K26: Not stated | L26: Not stated | M26: Not stated | N26: Conditional | O26: No English certificate is generally needed; the exception is projects involving the University of St Andrews, which requires evidence of English proficiency | P26: Not required | Q26: Central application via the online form; do not send applications to individual PIs. Project supervisors and a PI team review applications | R26: Guaranteed | S26: All students are supported: in Germany on the standard Max Planck PhD contract; in the UK at the national stipend rate, with St Andrews tuition covered | T26: Either | U26: Tri-institutional with the University of St Andrews; which university you register at depends on your entry qualifications, home country and project. Choose from the listed projects; own research proposals are not accepted. | V26: https://imprs-cpqm.mpg.de/apply-now | W26: 2026-10-21
A27: IMPRS Quantum Dynamics (Heidelberg) | B27: Max Planck Institute for Nuclear Physics (MPIK) and Heidelberg University · IMPRS for Quantum Dynamics in Physics, Chemistry and Biology (IMPRS-QD) | C27: Germany | D27: Baden-Württemberg | E27: 46327 | F27: Nov 1, 2026 for the 2026/2027 winter round (complete applications including reference letters) | G27: Not stated | I27: Not stated | J27: Not stated on the page checked | K27: Not stated | L27: Not stated | M27: Not stated | N27: Not stated | O27: Proof of English required if your mother tongue is not English or German; the page does not say whether an English-medium degree counts | P27: Not stated | Q27: No pre-application supervisor rule stated; short-listed candidates interview with their potential supervisors | R27: Competitive | S27: The school offers funding to selected students worldwide; admission is competitive and living-expense funding needs approval by the full IMPRS-QD Board | T27: Master's usually required | U27: Partners: MPIK, Heidelberg University, DKFZ, MPI for Medical Research, GSI Darmstadt. Physics students funded by IMPRS-QD are expected to join HGSFP; the online application link goes to the HGSFP portal. | V27: https://www.mpi-hd.mpg.de/imprs-qd/application/ | W27: 2026-10-21
A28: IMPRS Solar System (Göttingen) | B28: Max Planck Institute for Solar System Research (MPS), with University of Göttingen and TU Braunschweig · IMPRS for Solar System Science (Solar System School) | C28: Germany | D28: Lower Saxony | E28: Rolling | F28: Apply any time for advertised open projects; applications are reviewed in several rounds a year. The 2025/26 call rounds closed Feb 1, Jun 1 and Oct 1, 2026; dates for the next rounds were not yet published when checked | G28: Not stated | I28: Not stated | J28: Not stated on the page checked | K28: Not required | L28: Recommended | M28: Not stated | N28: Yes | O28: A degree from a course of study taught in English counts as proof of English; a test is needed only if your recent education was not in English or German for at least two years | P28: Not required | Q28: Contacting faculty first is not mandatory (it may help); a committee screens applications and the potential supervisor makes the final decision | R28: Typical | S28: Usually a doctoral support contract at 75% of TVöD E13 (about EUR 2,400 net/month on average); some students are on third-party scholarships. The 2025/26 call offered successful applicants a 3.5-year contract plus wrap-up funding | T28: Master's usually required | U28: Solar/stellar physics, planetary science and geoscience projects; choose up to three advertised open projects. Degree awarded by University of Göttingen or TU Braunschweig. The funding page says three-year contracts; the call and FAQ say 3.5 years. | V28: https://www.mps.mpg.de/phd/application | W28: 2026-10-21
A29: McGill | B29: McGill University · Department of Physics | C29: Canada | D29: Quebec | E29: 46371 | F29: December 15 for September (Fall) admission, international and domestic. Year inferred for Fall 2027. | G29: 120.99 | H29: CAD | I29: Not stated | J29: No waiver route stated on the pages checked | K29: Optional | L29: Recommended | M29: 86 | N29: Yes | O29: Normally exempt with a degree from a recognized foreign institution where English is the language of instruction; send proof to the department | P29: Recommended | Q29: Not required, but highly recommended: professors select students for their groups | R29: Guaranteed | S29: All graduate students receive a standard stipend, plus possible TA work | T29: Master's usually required | U29: The department FAQ answers 'Do I need to speak French?'; read it before applying. A Winter (January) intake also exists. | V29: https://www.physics.mcgill.ca/grads/application.html | W29: 2026-10-21
A30: McMaster | B30: McMaster University · Physics and Astronomy | C30: Canada | D30: Ontario | E30: 46419 | F30: No formal deadline (rolling, offers while funding lasts); international applicants strongly encouraged to apply by February 1 for internal scholarships. SGS: complete by January 31 for full scholarship consideration; considered until April 30. | G30: 150 | H30: CAD | I30: Not stated | J30: No waiver route stated on the pages checked | K30: Not stated | L30: Not stated | M30: Not stated | N30: Conditional | O30: The application asks whether your degree's official language of instruction AND evaluation was English; programs may add their own requirements | P30: Recommended | Q30: Funding includes a research fellowship from the supervisor's grant; contact faculty directly to ask if they are taking students | R30: Guaranteed | S30: Full support guaranteed for all admitted students (scholarship + supervisor research scholarship + TA); minimum at least CAD 21,000 after tuition and fees | T30: Not stated | U30: About 25 new MSc/PhD students per year; first offers often go out before Christmas, so earlier is better. | V30: https://physics.mcmaster.ca/graduate-studies/how-to-apply/ | W30: 2026-10-21
A31: North Carolina State University | B31: North Carolina State University · Department of Physics and Astronomy | C31: USA | D31: North Carolina | E31: 46391 | F31: Priority deadline January 4, 2027 for Fall 2027; in exceptional cases international applications accepted until March 1 | G31: 95 | H31: USD | I31: Domestic only | J31: Waiver only for the first 100 U.S.-citizen applicants with GPA above 3.0; department does not waive the fee for international students | K31: Optional | L31: Optional | M31: 80 | N31: Not stated | O31: Exempt if a citizen of a country where English is an official language and the language of instruction in higher education (FAQ says "the official language"); no country list on the pages checked, so India's status is not confirmed. Medium-of-instruction letters not mentioned. | P31: Not stated | Q31: Not stated on the page checked (candidate statement should list possible advisers) | R31: Typical | S31: Admits usually offered support; over 95% of students on TA/RA/fellowship (~$30,000/yr in Fall 2026) | T31: Direct from bachelor's | U31: International applicants are usually interviewed by Skype or phone. TA eligibility needs the SPEAK test plus higher IELTS speaking (7.0) or Duolingo sub-scores (125). Graduate School site (grad.ncsu.edu) could not be fetched (TLS failure). | V31: https://physics.sciences.ncsu.edu/graduate/apply/ | W31: 2026-10-21
A32: Penn State | B32: Penn State University (University Park) · Department of Physics | C32: USA | D32: Pennsylvania | E32: 46402 | F32: January 15 (applications for Fall 2027 open October 1, 2026). Year inferred. | G32: 0 | I32: Available | J32: Automatic for everyone this cycle via code PHYS2027 (international included) | K32: Not stated | L32: Not stated | M32: Not stated | N32: Not stated | O32: Rule is country-based ('non-English speaking countries'); exemption list not shown on the page checked | P32: Not stated | Q32: No pre-application supervisor requirement mentioned | R32: Not stated | S32: Not stated on the page checked | T32: Not stated | U32: Free to apply this cycle; a low-cost 'safety-to-target' add for many lists. | V32: https://science.psu.edu/physics/graduate/applying | W32: 2026-10-21
A33: Purdue | B33: Purdue University (West Lafayette) · Physics and Astronomy | C33: USA | D33: Indiana | E33: 46371 | F33: December 15 for fall, including TOEFL/IELTS scores. Year inferred for Fall 2027. | G33: 75 | H33: USD | I33: Limited | J33: Fee-waiver applications exist through Big Ten and Purdue; check eligibility for international applicants | K33: Optional | L33: Optional | M33: Not stated | N33: Not stated | O33: Exemption rules not shown on the pages checked | P33: Not stated | Q33: No pre-application supervisor requirement mentioned | R33: Typical | S33: Most common support is a half-time (20 h/week) teaching assistantship; tick the box on the main application | T33: Not stated | U33: Purdue states that from August 15, 2026, Indiana law requires additional review steps for some international applicants. Oral English certification is required to keep a TA appointment for non-native speakers. | V33: https://www.physics.purdue.edu/academic-programs/future_students/admissions.html | W33: 2026-10-21
A34: Queen's | B34: Queen's University · Physics, Engineering Physics and Astronomy | C34: Canada | D34: Ontario | E34: 46394 | F34: January 7 for full consideration (September start); rolling review so apply early. Year inferred. | G34: Not stated | I34: Not stated | J34: Not stated on the pages checked | K34: Optional | L34: Optional | M34: Not stated | N34: Conditional | O34: You may REQUEST an exemption if, in the 12 months before applying, you studied 1+ full year at a post-secondary institution where English is the official language of instruction | P34: Recommended | Q34: A complete application needs a research proposal; work with a potential supervisor early | R34: Guaranteed | S34: Minimum stipend guaranteed; PhD for four years (TA ~10 h/week in fall/winter contributes) | T34: Master's usually required | U34: Research proposal required. OGS applications due March 1. | V34: https://www.queensu.ca/physics/grad-studies/applicants | W34: 2026-10-21
A35: Rice | B35: Rice University · Physics and Astronomy | C35: USA | D35: Texas | E35: 46371 | F35: December 15, 2026, 11:59 EST; late applications considered until April 1, 2027 (less competitive) | G35: 85 | H35: USD | I35: Available | J35: Doctoral Fee Waiver Weeks open to students worldwide Oct 14-Nov 1, 2026 (or until waivers run out); completed application due Nov 27. Also waived for Texas/neighbouring-state students, GCURS speakers, Fulbright Scholars. | K35: Not considered | L35: Not considered | M35: 90 | N35: Not stated | O35: Exemption rules not shown on the department page checked | P35: Not stated | Q35: No pre-application supervisor requirement mentioned | R35: Not stated | S35: Not stated on the page checked | T35: Not stated | U35: Applied Physics is a separate Rice program with its own deadline and fee policy. | V35: https://physics.rice.edu/how-apply | W35: 2026-10-21
A36: Rutgers | B36: Rutgers University (New Brunswick) · Physics and Astronomy | C36: USA | D36: New Jersey | E36: 46388 | F36: Submit everything before January 1 for full financial-aid consideration (fall). Year inferred. | G36: Not stated | I36: Limited | J36: SGS auto-waives for certain groups; department can waive for a few applicants each year, usually used up months before the deadline - ask early | K36: Recommended | L36: Recommended | M36: Not stated | N36: Yes | O36: Exempt with 3+ years of undergraduate study or a master's where the mode of instruction was English | P36: Not stated | Q36: No pre-application supervisor requirement mentioned | R36: Guaranteed | S36: Department generally guarantees PhD support for 5 years | T36: Not stated | U36: Final decisions generally before April 15 for complete applications received by January. | V36: https://physics.rutgers.edu/academics/graduate-program/admissions | W36: 2026-10-21
A37: SISSA | B37: SISSA (Trieste) · PhD in Theory and Numerical Simulation of Condensed Matter | C37: Italy | D37: Friuli-Venezia Giulia (Trieste) | E37: Not stated | F37: Spring call closes early March each year (exact date in the call); a second call in September only if places remain. 2027 call not yet published. | G37: Not stated | I37: Not stated | J37: Not stated on the page checked | K37: Not stated | L37: Not stated | M37: Not stated | N37: Not stated | O37: Not stated on the page checked | P37: Not stated | Q37: Selection is a competition (qualifications, written exam, interview); no prior supervisor requirement mentioned | R37: Not stated | S37: Not stated on the page checked | T37: Not stated | U37: SISSA can contribute up to EUR 150 toward travel for the exams. Each SISSA physics group runs its own call and exam; this record covers Condensed Matter only. | V37: https://cm.sissa.it/phd/admission | W37: 2026-10-21
A38: SFU | B38: Simon Fraser University · Department of Physics | C38: Canada | D38: British Columbia | E38: 46402 | F38: Apply before January 15 (better chance at desired group and awards); system open until May 31. Year inferred. | G38: 150 | H38: CAD | I38: Not stated | J38: Not stated on the pages checked | K38: Not stated | L38: Not stated | M38: Not stated | N38: No | O38: Exempt only if BOTH: degree taught and examined in English AND institution in an English-primary country (list linked); otherwise submit scores | P38: Not stated | Q38: Not stated in the text checked; transfers need supervisory committee approval | R38: Not stated | S38: Not stated on the pages checked | T38: Master's usually required | U38: PhD starts possible in September, January or May. | V38: https://www.sfu.ca/physics/graduate/prospective/applying.html | W38: 2026-10-21
A39: Stanford | B39: Stanford University · Department of Physics | C39: USA | D39: California | E39: 46370 | F39: 11:59pm PST, December 14, 2026 (no late applications); Knight-Hennessy applicants: physics application by December 1, 2026 | G39: Not stated | I39: Limited | J39: Some applicants may qualify; see Stanford Graduate Admissions fee-waiver page for eligibility | K39: Required | L39: Required | M39: Not stated | N39: Yes | O39: Not required if your degree (or international equivalent) is from a university where ALL instruction was in English; no documents needed at application | P39: Not stated | Q39: No pre-application supervisor requirement mentioned (you choose theory/experiment/astro area) | R39: Guaranteed | S39: Department provides financial support for all enrolled students | T39: Not stated | U39: Two GRE requirements make Stanford one of the most test-heavy programs this cycle. | V39: https://physics.stanford.edu/graduate/graduate-admissions | W39: 2026-10-21
A40: Stockholm | B40: Stockholm University · Department of Physics (Fysikum) | C40: Sweden | D40: Stockholm | E40: Per position | F40: No central deadline: positions are advertised on the department vacancies page about four times a year (normally Feb, Apr, Sep, Oct), each with its own deadline. The page lists only 2025 dates | G40: Not stated | I40: Not stated | J40: Not stated on the page checked | K40: Not stated | L40: Not stated | M40: 79 | N40: Yes | O40: A previously completed university degree taught in English is listed as meeting the English requirement (as an alternative to IELTS/TOEFL) | P40: Required | Q40: You apply to a specific advertised position and are assessed against the other applicants for it; at least two supervisors are appointed in connection with admission | R40: Guaranteed | S40: Funding for the whole study period (normally 4 years) is a condition of admission; in most cases you are employed as a PhD student with a salary | T40: Master's usually required | U40: Fysikum's doctoral subjects are Physics, Theoretical Physics, Chemical Physics and Medical Radiation Physics. Applicants not known from SU undergraduate studies normally have to show their qualifications by taking one or two advanced-level courses or doing a suitable project (eligibility page). The call dates on the page are for 2025; check the department vacancies page for the 2026-27 calls. | V40: https://www.su.se/english/divisions/department-of-physics/education/courses-and-programmes/doctoral-studies-at-the-department-of-physics | W40: 2026-10-21
...

Sheet Shortlist
A1: Program (choose) | B1: Country | C1: Deadline | D1: Days left | E1: Fee | F1: Currency | G1: Intl fee waiver | H1: Physics GRE | I1: English waiver | J1: Supervisor | K1: Status | L1: SOP ready | M1: Letters confirmed | N1: Fee paid / waiver | O1: My notes
B2: =IF($A2="","",INDEX(Programs!$C$2:$C$83,MATCH($A2,Programs!$A$2:$A$83,0))) | C2: =IF($A2="","",INDEX(Programs!$E$2:$E$83,MATCH($A2,Programs!$A$2:$A$83,0))) | D2: =IF(ISNUMBER(C2),C2-TODAY(),"") | E2: =IF($A2="","",INDEX(Programs!$G$2:$G$83,MATCH($A2,Programs!$A$2:$A$83,0))) | F2: =IF($A2="","",INDEX(Programs!$H$2:$H$83,MATCH($A2,Programs!$A$2:$A$83,0))) | G2: =IF($A2="","",INDEX(Programs!$I$2:$I$83,MATCH($A2,Programs!$A$2:$A$83,0))) | H2: =IF($A2="","",INDEX(Programs!$L$2:$L$83,MATCH($A2,Programs!$A$2:$A$83,0))) | I2: =IF($A2="","",INDEX(Programs!$N$2:$N$83,MATCH($A2,Programs!$A$2:$A$83,0))) | J2: =IF($A2="","",INDEX(Programs!$P$2:$P$83,MATCH($A2,Programs!$A$2:$A$83,0)))
B3: =IF($A3="","",INDEX(Programs!$C$2:$C$83,MATCH($A3,Programs!$A$2:$A$83,0))) | C3: =IF($A3="","",INDEX(Programs!$E$2:$E$83,MATCH($A3,Programs!$A$2:$A$83,0))) | D3: =IF(ISNUMBER(C3),C3-TODAY(),"") | E3: =IF($A3="","",INDEX(Programs!$G$2:$G$83,MATCH($A3,Programs!$A$2:$A$83,0))) | F3: =IF($A3="","",INDEX(Programs!$H$2:$H$83,MATCH($A3,Programs!$A$2:$A$83,0))) | G3: =IF($A3="","",INDEX(Programs!$I$2:$I$83,MATCH($A3,Programs!$A$2:$A$83,0))) | H3: =IF($A3="","",INDEX(Programs!$L$2:$L$83,MATCH($A3,Programs!$A$2:$A$83,0))) | I3: =IF($A3="","",INDEX(Programs!$N$2:$N$83,MATCH($A3,Programs!$A$2:$A$83,0))) | J3: =IF($A3="","",INDEX(Programs!$P$2:$P$83,MATCH($A3,Programs!$A$2:$A$83,0)))
B4: =IF($A4="","",INDEX(Programs!$C$2:$C$83,MATCH($A4,Programs!$A$2:$A$83,0))) | C4: =IF($A4="","",INDEX(Programs!$E$2:$E$83,MATCH($A4,Programs!$A$2:$A$83,0))) | D4: =IF(ISNUMBER(C4),C4-TODAY(),"") | E4: =IF($A4="","",INDEX(Programs!$G$2:$G$83,MATCH($A4,Programs!$A$2:$A$83,0))) | F4: =IF($A4="","",INDEX(Programs!$H$2:$H$83,MATCH($A4,Programs!$A$2:$A$83,0))) | G4: =IF($A4="","",INDEX(Programs!$I$2:$I$83,MATCH($A4,Programs!$A$2:$A$83,0))) | H4: =IF($A4="","",INDEX(Programs!$L$2:$L$83,MATCH($A4,Programs!$A$2:$A$83,0))) | I4: =IF($A4="","",INDEX(Programs!$N$2:$N$83,MATCH($A4,Programs!$A$2:$A$83,0))) | J4: =IF($A4="","",INDEX(Programs!$P$2:$P$83,MATCH($A4,Programs!$A$2:$A$83,0)))
B5: =IF($A5="","",INDEX(Programs!$C$2:$C$83,MATCH($A5,Programs!$A$2:$A$83,0))) | C5: =IF($A5="","",INDEX(Programs!$E$2:$E$83,MATCH($A5,Programs!$A$2:$A$83,0))) | D5: =IF(ISNUMBER(C5),C5-TODAY(),"") | E5: =IF($A5="","",INDEX(Programs!$G$2:$G$83,MATCH($A5,Programs!$A$2:$A$83,0))) | F5: =IF($A5="","",INDEX(Programs!$H$2:$H$83,MATCH($A5,Programs!$A$2:$A$83,0))) | G5: =IF($A5="","",INDEX(Programs!$I$2:$I$83,MATCH($A5,Programs!$A$2:$A$83,0))) | H5: =IF($A5="","",INDEX(Programs!$L$2:$L$83,MATCH($A5,Programs!$A$2:$A$83,0))) | I5: =IF($A5="","",INDEX(Programs!$N$2:$N$83,MATCH($A5,Programs!$A$2:$A$83,0))) | J5: =IF($A5="","",INDEX(Programs!$P$2:$P$83,MATCH($A5,Programs!$A$2:$A$83,0)))
B6: =IF($A6="","",INDEX(Programs!$C$2:$C$83,MATCH($A6,Programs!$A$2:$A$83,0))) | C6: =IF($A6="","",INDEX(Programs!$E$2:$E$83,MATCH($A6,Programs!$A$2:$A$83,0))) | D6: =IF(ISNUMBER(C6),C6-TODAY(),"") | E6: =IF($A6="","",INDEX(Programs!$G$2:$G$83,MATCH($A6,Programs!$A$2:$A$83,0))) | F6: =IF($A6="","",INDEX(Programs!$H$2:$H$83,MATCH($A6,Programs!$A$2:$A$83,0))) | G6: =IF($A6="","",INDEX(Programs!$I$2:$I$83,MATCH($A6,Programs!$A$2:$A$83,0))) | H6: =IF($A6="","",INDEX(Programs!$L$2:$L$83,MATCH($A6,Programs!$A$2:$A$83,0))) | I6: =IF($A6="","",INDEX(Programs!$N$2:$N$83,MATCH($A6,Programs!$A$2:$A$83,0))) | J6: =IF($A6="","",INDEX(Programs!$P$2:$P$83,MATCH($A6,Programs!$A$2:$A$83,0)))
B7: =IF($A7="","",INDEX(Programs!$C$2:$C$83,MATCH($A7,Programs!$A$2:$A$83,0))) | C7: =IF($A7="","",INDEX(Programs!$E$2:$E$83,MATCH($A7,Programs!$A$2:$A$83,0))) | D7: =IF(ISNUMBER(C7),C7-TODAY(),"") | E7: =IF($A7="","",INDEX(Programs!$G$2:$G$83,MATCH($A7,Programs!$A$2:$A$83,0))) | F7: =IF($A7="","",INDEX(Programs!$H$2:$H$83,MATCH($A7,Programs!$A$2:$A$83,0))) | G7: =IF($A7="","",INDEX(Programs!$I$2:$I$83,MATCH($A7,Programs!$A$2:$A$83,0))) | H7: =IF($A7="","",INDEX(Programs!$L$2:$L$83,MATCH($A7,Programs!$A$2:$A$83,0))) | I7: =IF($A7="","",INDEX(Programs!$N$2:$N$83,MATCH($A7,Programs!$A$2:$A$83,0))) | J7: =IF($A7="","",INDEX(Programs!$P$2:$P$83,MATCH($A7,Programs!$A$2:$A$83,0)))
B8: =IF($A8="","",INDEX(Programs!$C$2:$C$83,MATCH($A8,Programs!$A$2:$A$83,0))) | C8: =IF($A8="","",INDEX(Programs!$E$2:$E$83,MATCH($A8,Programs!$A$2:$A$83,0))) | D8: =IF(ISNUMBER(C8),C8-TODAY(),"") | E8: =IF($A8="","",INDEX(Programs!$G$2:$G$83,MATCH($A8,Programs!$A$2:$A$83,0))) | F8: =IF($A8="","",INDEX(Programs!$H$2:$H$83,MATCH($A8,Programs!$A$2:$A$83,0))) | G8: =IF($A8="","",INDEX(Programs!$I$2:$I$83,MATCH($A8,Programs!$A$2:$A$83,0))) | H8: =IF($A8="","",INDEX(Programs!$L$2:$L$83,MATCH($A8,Programs!$A$2:$A$83,0))) | I8: =IF($A8="","",INDEX(Programs!$N$2:$N$83,MATCH($A8,Programs!$A$2:$A$83,0))) | J8: =IF($A8="","",INDEX(Programs!$P$2:$P$83,MATCH($A8,Programs!$A$2:$A$83,0)))
B9: =IF($A9="","",INDEX(Programs!$C$2:$C$83,MATCH($A9,Programs!$A$2:$A$83,0))) | C9: =IF($A9="","",INDEX(Programs!$E$2:$E$83,MATCH($A9,Programs!$A$2:$A$83,0))) | D9: =IF(ISNUMBER(C9),C9-TODAY(),"") | E9: =IF($A9="","",INDEX(Programs!$G$2:$G$83,MATCH($A9,Programs!$A$2:$A$83,0))) | F9: =IF($A9="","",INDEX(Programs!$H$2:$H$83,MATCH($A9,Programs!$A$2:$A$83,0))) | G9: =IF($A9="","",INDEX(Programs!$I$2:$I$83,MATCH($A9,Programs!$A$2:$A$83,0))) | H9: =IF($A9="","",INDEX(Programs!$L$2:$L$83,MATCH($A9,Programs!$A$2:$A$83,0))) | I9: =IF($A9="","",INDEX(Programs!$N$2:$N$83,MATCH($A9,Programs!$A$2:$A$83,0))) | J9: =IF($A9="","",INDEX(Programs!$P$2:$P$83,MATCH($A9,Programs!$A$2:$A$83,0)))
B10: =IF($A10="","",INDEX(Programs!$C$2:$C$83,MATCH($A10,Programs!$A$2:$A$83,0))) | C10: =IF($A10="","",INDEX(Programs!$E$2:$E$83,MATCH($A10,Programs!$A$2:$A$83,0))) | D10: =IF(ISNUMBER(C10),C10-TODAY(),"") | E10: =IF($A10="","",INDEX(Programs!$G$2:$G$83,MATCH($A10,Programs!$A$2:$A$83,0))) | F10: =IF($A10="","",INDEX(Programs!$H$2:$H$83,MATCH($A10,Programs!$A$2:$A$83,0))) | G10: =IF($A10="","",INDEX(Programs!$I$2:$I$83,MATCH($A10,Programs!$A$2:$A$83,0))) | H10: =IF($A10="","",INDEX(Programs!$L$2:$L$83,MATCH($A10,Programs!$A$2:$A$83,0))) | I10: =IF($A10="","",INDEX(Programs!$N$2:$N$83,MATCH($A10,Programs!$A$2:$A$83,0))) | J10: =IF($A10="","",INDEX(Programs!$P$2:$P$83,MATCH($A10,Programs!$A$2:$A$83,0)))
B11: =IF($A11="","",INDEX(Programs!$C$2:$C$83,MATCH($A11,Programs!$A$2:$A$83,0))) | C11: =IF($A11="","",INDEX(Programs!$E$2:$E$83,MATCH($A11,Programs!$A$2:$A$83,0))) | D11: =IF(ISNUMBER(C11),C11-TODAY(),"") | E11: =IF($A11="","",INDEX(Programs!$G$2:$G$83,MATCH($A11,Programs!$A$2:$A$83,0))) | F11: =IF($A11="","",INDEX(Programs!$H$2:$H$83,MATCH($A11,Programs!$A$2:$A$83,0))) | G11: =IF($A11="","",INDEX(Programs!$I$2:$I$83,MATCH($A11,Programs!$A$2:$A$83,0))) | H11: =IF($A11="","",INDEX(Programs!$L$2:$L$83,MATCH($A11,Programs!$A$2:$A$83,0))) | I11: =IF($A11="","",INDEX(Programs!$N$2:$N$83,MATCH($A11,Programs!$A$2:$A$83,0))) | J11: =IF($A11="","",INDEX(Programs!$P$2:$P$83,MATCH($A11,Programs!$A$2:$A$83,0)))
B12: =IF($A12="","",INDEX(Programs!$C$2:$C$83,MATCH($A12,Programs!$A$2:$A$83,0))) | C12: =IF($A12="","",INDEX(Programs!$E$2:$E$83,MATCH($A12,Programs!$A$2:$A$83,0))) | D12: =IF(ISNUMBER(C12),C12-TODAY(),"") | E12: =IF($A12="","",INDEX(Programs!$G$2:$G$83,MATCH($A12,Programs!$A$2:$A$83,0))) | F12: =IF($A12="","",INDEX(Programs!$H$2:$H$83,MATCH($A12,Programs!$A$2:$A$83,0))) | G12: =IF($A12="","",INDEX(Programs!$I$2:$I$83,MATCH($A12,Programs!$A$2:$A$83,0))) | H12: =IF($A12="","",INDEX(Programs!$L$2:$L$83,MATCH($A12,Programs!$A$2:$A$83,0))) | I12: =IF($A12="","",INDEX(Programs!$N$2:$N$83,MATCH($A12,Programs!$A$2:$A$83,0))) | J12: =IF($A12="","",INDEX(Programs!$P$2:$P$83,MATCH($A12,Programs!$A$2:$A$83,0)))
B13: =IF($A13="","",INDEX(Programs!$C$2:$C$83,MATCH($A13,Programs!$A$2:$A$83,0))) | C13: =IF($A13="","",INDEX(Programs!$E$2:$E$83,MATCH($A13,Programs!$A$2:$A$83,0))) | D13: =IF(ISNUMBER(C13),C13-TODAY(),"") | E13: =IF($A13="","",INDEX(Programs!$G$2:$G$83,MATCH($A13,Programs!$A$2:$A$83,0))) | F13: =IF($A13="","",INDEX(Programs!$H$2:$H$83,MATCH($A13,Programs!$A$2:$A$83,0))) | G13: =IF($A13="","",INDEX(Programs!$I$2:$I$83,MATCH($A13,Programs!$A$2:$A$83,0))) | H13: =IF($A13="","",INDEX(Programs!$L$2:$L$83,MATCH($A13,Programs!$A$2:$A$83,0))) | I13: =IF($A13="","",INDEX(Programs!$N$2:$N$83,MATCH($A13,Programs!$A$2:$A$83,0))) | J13: =IF($A13="","",INDEX(Programs!$P$2:$P$83,MATCH($A13,Programs!$A$2:$A$83,0)))
... B31: =IF($A31="","",INDEX(Programs!$C$2:$C$83,MATCH($A31,Programs!$A$2:$A$83,0))) | C31: =IF($A31="","",INDEX(Programs!$E$2:$E$83,MATCH($A31,Programs!$A$2:$A$83,0))) | D31: =IF(ISNUMBER(C31),C31-TODAY(),"") | E31: =IF($A31="","",INDEX(Programs!$G$2:$G$83,MATCH($A31,Programs!$A$2:$A$83,0))) | F31: =IF($A31="","",INDEX(Programs!$H$2:$H$83,MATCH($A31,Programs!$A$2:$A$83,0))) | G31: =IF($A31="","",INDEX(Programs!$I$2:$I$83,MATCH($A31,Programs!$A$2:$A$83,0))) | H31: =IF($A31="","",INDEX(Programs!$L$2:$L$83,MATCH($A31,Programs!$A$2:$A$83,0))) | I31: =IF($A31="","",INDEX(Programs!$N$2:$N$83,MATCH($A31,Programs!$A$2:$A$83,0))) | J31: =IF($A31="","",INDEX(Programs!$P$2:$P$83,MATCH($A31,Programs!$A$2:$A$83,0)))

Sheet Budget
A1: Item | B1: USD | C1: CAD | D1: GBP | E1: EUR | F1: CHF | G1: Notes
A2: Application fees on your shortlist (excludes rows marked Waived) | B2: =SUMIFS(Shortlist!$E$2:$E$31,Shortlist!$F$2:$F$31,"USD",Shortlist!$N$2:$N$31,"<>Waived") | C2: =SUMIFS(Shortlist!$E$2:$E$31,Shortlist!$F$2:$F$31,"CAD",Shortlist!$N$2:$N$31,"<>Waived") | D2: =SUMIFS(Shortlist!$E$2:$E$31,Shortlist!$F$2:$F$31,"GBP",Shortlist!$N$2:$N$31,"<>Waived") | E2: =SUMIFS(Shortlist!$E$2:$E$31,Shortlist!$F$2:$F$31,"EUR",Shortlist!$N$2:$N$31,"<>Waived") | F2: =SUMIFS(Shortlist!$E$2:$E$31,Shortlist!$F$2:$F$31,"CHF",Shortlist!$N$2:$N$31,"<>Waived") | G2: Calculated
A3: English test (booking + extra score reports) | G3: Enter from the official test website
A4: GRE / Physics GRE (booking + score reports) | G4: Enter only if a program on your list needs it
A5: Transcripts, credential evaluation, courier | G5: Enter from your university / evaluator
A6: Other
A7: Total | B7: =SUM(B2:B6) | C7: =SUM(C2:C6) | D7: =SUM(D2:D6) | E7: =SUM(E2:E6) | F7: =SUM(F2:F6)
A9: Rupees per 1 unit (Bank of Canada, 2026-10-21): edit to today's rate, or your own currency | B9: 94.47 | C9: 67.2 | D9: 126.52 | E9: 106.08 | F9: 114.56 | G9: Pre-filled; banks and cards add a margin
A10: Total in rupees (approximate) | B10: =IF(B9="",0,B7*B9)+IF(C9="",0,C7*C9)+IF(D9="",0,D7*D9)+IF(E9="",0,E7*E9)+IF(F9="",0,F7*F9) | G10: Currencies without a rate are left out

Sheet Recommenders
A1: Recommender | B1: Email | C1: Relationship | D1: Asked on | E1: Packet sent | F1: Programs invited | G1: Status | H1: Follow up by
H2: =IF(D2="","",D2+14)
H3: =IF(D3="","",D3+14)
H4: =IF(D4="","",D4+14)
H5: =IF(D5="","",D5+14)
H6: =IF(D6="","",D6+14)
H7: =IF(D7="","",D7+14)
H8: =IF(D8="","",D8+14)

Sheet Supervisor outreach
A1: Professor | B1: University | C1: Group / topic | D1: Paper you read | E1: Emailed on | F1: Follow up on | G1: Reply | H1: Next step
F2: =IF(E2="","",E2+10)
F3: =IF(E3="","",E3+10)
F4: =IF(E4="","",E4+10)
F5: =IF(E5="","",E5+10)
F6: =IF(E6="","",E6+10)
F7: =IF(E7="","",E7+10)
F8: =IF(E8="","",E8+10)
F9: =IF(E9="","",E9+10)
F10: =IF(E10="","",E10+10)
F11: =IF(E11="","",E11+10)
F12: =IF(E12="","",E12+10)
F13: =IF(E13="","",E13+10)
... F30: =IF(E30="","",E30+10)

Sheet Sources
A1: Program | B1: Field | C1: Code | D1: Value | E1: Official quote | F1: Source URL | G1: Flags | H1: Checked
A2: Aalto University | B2: Deadline (2027 entry) | C2: Rolling | D2: Continuous admission with roughly monthly cut-offs (nothing is processed in July); the last 2026 cut-offs are 3 Nov and 1 Dec 2026. Salaried doctoral researcher positions are advertised and applied for separately | E2: The Doctoral Programme in Science invites applications continuously (applications will not be processed in July). | Tue 3.11.2026 | Tue 1.12.2026 || Salaried doctoral researcher positions are applied for separately from the admission process to the doctoral programme. (https://www.aalto.fi/en/doctoral-education/how-to-apply-for-doctoral-studies) | F2: https://www.aalto.fi/en/study-options/aalto-doctoral-programme-in-science-0 | H2: 2026-10-21
A3: Aalto University | B3: Application fee | C3: Not stated | D3: Not stated on the page checked | E3: (no statement found) | F3: https://www.aalto.fi/en/study-options/aalto-doctoral-programme-in-science-0 | H3: 2026-10-21
